Workbook

Sheet HR Activity Log
A1: Employee_ID | B1: Employee_Name | C1: Department | D1: Job_Title | E1: Activity_Type | F1: Activity_Description | G1: Activity_Date | H1: Duration_Hours | I1: Employees_Impacted | J1: Cost_Center | K1: Priority | L1: Status | M1: Notes
A2: HR001 | B2: Jordan Ellis | C2: Talent Acquisition | D2: Senior Recruiter | E2: Recruiting | F2: Sourced 12 candidates via LinkedIn Recruiter | G2: 2026-03-02 | H2: 3 | I2: 0 | J2: TA | K2: High | L2: Completed | M2: Used Boolean search strings
A3: HR001 | B3: Jordan Ellis | C3: Talent Acquisition | D3: Senior Recruiter | E3: Recruiting | F3: Conducted 4 phone screens for Software Engineer role | G3: 2026-03-03 | H3: 4 | I3: 4 | J3: TA | K3: High | L3: Completed | M3: 2 advanced to next round
A4: HR001 | B4: Jordan Ellis | C4: Talent Acquisition | D4: Senior Recruiter | E4: Recruiting | F4: Coordinated 3 panel interviews | G4: 2026-03-05 | H4: 3 | I4: 3 | J4: TA | K4: High | L4: Completed | M4: Debrief session held same day
A5: HR001 | B5: Jordan Ellis | C5: Talent Acquisition | D5: Senior Recruiter | E5: Offer Management | F5: Extended 2 job offers and negotiated compensation | G5: 2026-03-08 | H5: 2 | I5: 2 | J5: TA | K5: High | L5: Completed | M5: 1 accepted, 1 countered
A6: HR001 | B6: Jordan Ellis | C6: Talent Acquisition | D6: Senior Recruiter | E6: Employer Branding | F6: Updated Glassdoor responses and LinkedIn company page | G6: 2026-03-10 | H6: 1 | I6: 0 | J6: TA | K6: Medium | L6: Completed
A7: HR002 | B7: Priya Nair | C7: Talent Acquisition | D7: Talent Acquisition Coordinator | E7: Onboarding | F7: Prepared new hire packets for 3 employees | G7: 2026-03-01 | H7: 2 | I7: 3 | J7: TA | K7: High | L7: Completed | M7: Included I-9, W-4, benefits enrollment
A8: HR002 | B8: Priya Nair | C8: Talent Acquisition | D8: Talent Acquisition Coordinator | E8: Onboarding | F8: Conducted Day 1 orientation session | G8: 2026-03-04 | H8: 4 | I8: 3 | J8: TA | K8: High | L8: Completed | M8: Covered culture, systems, policies
A9: HR002 | B9: Priya Nair | C9: Talent Acquisition | D9: Talent Acquisition Coordinator | E9: Recruiting | F9: Posted 5 job openings across 3 job boards | G9: 2026-03-06 | H9: 1 | I9: 0 | J9: TA | K9: Medium | L9: Completed | M9: Indeed, LinkedIn, Handshake
A10: HR002 | B10: Priya Nair | C10: Talent Acquisition | D10: Talent Acquisition Coordinator | E10: Background Check | F10: Initiated background checks for 4 candidates | G10: 2026-03-07 | H10: 1 | I10: 4 | J10: TA | K10: High | L10: Completed | M10: All cleared within 3 days
A11: HR002 | B11: Priya Nair | C11: Talent Acquisition | D11: Talent Acquisition Coordinator | E11: Onboarding | F11: 30-day check-in meetings with new hires | G11: 2026-03-15 | H11: 2 | I11: 3 | J11: TA | K11: Medium | L11: Completed | M11: All employees adjusting well
A12: HR003 | B12: Marcus Webb | C12: HR Business Partner | D12: Sr. HR Business Partner | E12: Performance Management | F12: Facilitated Q1 performance calibration for Sales dept | G12: 2026-03-03 | H12: 4 | I12: 45 | J12: HRBP | K12: High | L12: Completed | M12: Ratings normalized across managers
A13: HR003 | B13: Marcus Webb | C13: HR Business Partner | D13: Sr. HR Business Partner | E13: Employee Relations | F13: Investigated workplace harassment complaint | G13: 2026-03-06 | H13: 6 | I13: 2 | J13: HRBP | K13: Critical | L13: Completed | M13: Substantiated; written warning issued
A14: HR003 | B14: Marcus Webb | C14: HR Business Partner | D14: Sr. HR Business Partner | E14: Performance Management | F14: Developed PIP for underperforming employee | G14: 2026-03-09 | H14: 3 | I14: 1 | J14: HRBP | K14: High | L14: Completed | M14: 90-day plan with bi-weekly check-ins
A15: HR003 | B15: Marcus Webb | C15: HR Business Partner | D15: Sr. HR Business Partner | E15: Workforce Planning | F15: Met with VP Sales on Q2 headcount needs | G15: 2026-03-11 | H15: 2 | I15: 1 | J15: HRBP | K15: High | L15: Completed | M15: 3 new req approvals requested
A16: HR003 | B16: Marcus Webb | C16: HR Business Partner | D16: Sr. HR Business Partner | E16: HR Consulting | F16: Coached manager on difficult performance conversation | G16: 2026-03-13 | H16: 1 | I16: 1 | J16: HRBP | K16: Medium | L16: Completed
A17: HR004 | B17: Aisha Okafor | C17: HR Business Partner | D17: HR Business Partner | E17: Employee Relations | F17: Mediated conflict between two team leads | G17: 2026-03-02 | H17: 3 | I17: 2 | J17: HRBP | K17: High | L17: Completed | M17: Resolved; follow-up in 2 weeks
A18: HR004 | B18: Aisha Okafor | C18: HR Business Partner | D18: HR Business Partner | E18: Policy Update | F18: Revised remote work policy per new state regulations | G18: 2026-03-04 | H18: 4 | I18: 320 | J18: HRBP | K18: High | L18: Completed | M18: Distributed company-wide
A19: HR004 | B19: Aisha Okafor | C19: HR Business Partner | D19: HR Business Partner | E19: HR Consulting | F19: Advised manager on FMLA leave process | G19: 2026-03-07 | H19: 1 | I19: 1 | J19: HRBP | K19: Medium | L19: Completed | M19: Employee filed paperwork same day
A20: HR004 | B20: Aisha Okafor | C20: HR Business Partner | D20: HR Business Partner | E20: Offboarding | F20: Exit interview and separation processing for 2 employees | G20: 2026-03-12 | H20: 3 | I20: 2 | J20: HRBP | K20: High | L20: Completed | M20: Voluntary resignations; feedback captured
A21: HR004 | B21: Aisha Okafor | C21: HR Business Partner | D21: HR Business Partner | E21: Reporting | F21: Prepared Q1 turnover report for CHRO | G21: 2026-03-14 | H21: 2 | I21: 1 | J21: HRBP | K21: Medium | L21: Completed | M21: 12.4% annualized turnover rate
A22: HR005 | B22: Diana Chen | C22: Compensation & Benefits | D22: Compensation Analyst | E22: Compensation Review | F22: Benchmarked 18 roles against Radford survey data | G22: 2026-03-02 | H22: 6 | I22: 18 | J22: C&B | K22: High | L22: Completed | M22: 8 roles flagged as below market
A23: HR005 | B23: Diana Chen | C23: Compensation & Benefits | D23: Compensation Analyst | E23: Compensation Review | F23: Built merit increase model for Q2 cycle | G23: 2026-03-05 | H23: 5 | I23: 320 | J23: C&B | K23: High | L23: Completed | M23: 2.5% budget modeled
A24: HR005 | B24: Diana Chen | C24: Compensation & Benefits | D24: Compensation Analyst | E24: Benefits Administration | F24: Resolved 6 benefits enrollment errors | G24: 2026-03-08 | H24: 3 | I24: 6 | J24: C&B | K24: High | L24: Completed | M24: Carrier discrepancies corrected
A25: HR005 | B25: Diana Chen | C25: Compensation & Benefits | D25: Compensation Analyst | E25: Benefits Administration | F25: Presented open enrollment overview to new hires | G25: 2026-03-11 | H25: 2 | I25: 3 | J25: C&B | K25: Medium | L25: Completed
A26: HR005 | B26: Diana Chen | C26: Compensation & Benefits | D26: Compensation Analyst | E26: Reporting | F26: Submitted annual EEO-1 pay data report | G26: 2026-03-15 | H26: 4 | I26: 320 | J26: C&B | K26: Critical | L26: Completed | M26: Filed with EEOC on time
A27: HR006 | B27: Tomás Rivera | C27: Compensation & Benefits | D27: Benefits Specialist | E27: Benefits Administration | F27: Processed 401k enrollment for 8 employees | G27: 2026-03-01 | H27: 2 | I27: 8 | J27: C&B | K27: High | L27: Completed | M27: Contributions effective next pay period
A28: HR006 | B28: Tomás Rivera | C28: Compensation & Benefits | D28: Benefits Specialist | E28: Benefits Administration | F28: Handled 5 FSA reimbursement issues | G28: 2026-03-04 | H28: 2 | I28: 5 | J28: C&B | K28: Medium | L28: Completed
A29: HR006 | B29: Tomás Rivera | C29: Compensation & Benefits | D29: Benefits Specialist | E29: FMLA/Leave | F29: Processed 3 FMLA leave requests | G29: 2026-03-07 | H29: 3 | I29: 3 | J29: C&B | K29: High | L29: Completed | M29: Paperwork sent to employees
A30: HR006 | B30: Tomás Rivera | C30: Compensation & Benefits | D30: Benefits Specialist | E30: Benefits Administration | F30: Renewal meeting with health insurance broker | G30: 2026-03-10 | H30: 2 | I30: 320 | J30: C&B | K30: High | L30: Completed | M30: Rates increase 6.2% in July
A31: HR006 | B31: Tomás Rivera | C31: Compensation & Benefits | D31: Benefits Specialist | E31: Benefits Administration | F31: Workers' comp claim intake for 1 employee | G31: 2026-03-13 | H31: 1 | I31: 1 | J31: C&B | K31: High | L31: Completed | M31: Claim submitted to carrier
A32: HR007 | B32: Keisha Daniels | C32: Payroll | D32: Payroll Manager | E32: Payroll | F32: Processed semi-monthly payroll for 320 employees | G32: 2026-03-05 | H32: 6 | I32: 320 | J32: PAY | K32: Critical | L32: Completed | M32: No exceptions; ACH submitted on time
A33: HR007 | B33: Keisha Daniels | C33: Payroll | D33: Payroll Manager | E33: Payroll | F33: Processed off-cycle payroll for 2 terminations | G33: 2026-03-08 | H33: 2 | I33: 2 | J33: PAY | K33: High | L33: Completed | M33: Final pay with accrued PTO
A34: HR007 | B34: Keisha Daniels | C34: Payroll | D34: Payroll Manager | E34: Compliance | F34: Reconciled Q1 941 payroll tax filing | G34: 2026-03-12 | H34: 4 | I34: 320 | J34: PAY | K34: Critical | L34: Completed | M34: Submitted to IRS; no discrepancies
A35: HR007 | B35: Keisha Daniels | C35: Payroll | D35: Payroll Manager | E35: Reporting | F35: Generated labor cost report by department for CFO | G35: 2026-03-14 | H35: 3 | I35: 1 | J35: PAY | K35: High | L35: Completed | M35: Shared via Workday
A36: HR007 | B36: Keisha Daniels | C36: Payroll | D36: Payroll Manager | E36: Payroll | F36: Updated direct deposit info for 4 employees | G36: 2026-03-15 | H36: 1 | I36: 4 | J36: PAY | K36: Medium | L36: Completed
A37: HR008 | B37: Samira Patel | C37: Learning & Development | D37: L&D Specialist | E37: Training | F37: Delivered unconscious bias training (2 sessions) | G37: 2026-03-03 | H37: 6 | I37: 40 | J37: L&D | K37: High | L37: Completed | M37: Average satisfaction: 4.6/5
A38: HR008 | B38: Samira Patel | C38: Learning & Development | D38: L&D Specialist | E38: Training | F38: Designed new manager onboarding curriculum | G38: 2026-03-06 | H38: 5 | I38: 0 | J38: L&D | K38: High | L38: In Progress | M38: Draft 1 complete; review pending
A39: HR008 | B39: Samira Patel | C39: Learning & Development | D39: L&D Specialist | E39: Training | F39: Facilitated conflict resolution workshop | G39: 2026-03-09 | H39: 4 | I39: 18 | J39: L&D | K39: Medium | L39: Completed | M39: Interactive role-play used
A40: HR008 | B40: Samira Patel | C40: Learning & Development | D40: L&D Specialist | E40: Training | F40: Coordinated compliance training (HIPAA, harassment) | G40: 2026-03-11 | H40: 3 | I40: 320 | J40: L&D | K40: Critical | L40: Completed | M40: 100% completion tracked in LMS
...

Sheet Employee Compensation
A1: Employee_ID | B1: Employee_Name | C1: Department | D1: Job_Title | E1: Level | F1: Employment_Type | G1: Annual_Base_Salary | H1: Annual_Bonus_Target_Pct | I1: Annual_Bonus_Target_Amt | J1: Annual_Equity_Grant | K1: Total_Target_Comp | L1: Health_Benefits_ER | M1: 401k_Match_ER | N1: Other_Benefits_ER | O1: Total_Benefits_Cost_ER | P1: Total_Cost_to_Company | Q1: Hire_Date | R1: Pay_Frequency | S1: FLSA_Status | T1: Location
A2: HR001 | B2: Jordan Ellis | C2: Talent Acquisition | D2: Senior Recruiter | E2: L3 | F2: Full-Time | G2: 85000 | H2: 0.1 | I2: =G2*H2 | J2: 0 | K2: =G2+I2+J2 | L2: 9600 | M2: 4250 | N2: 1200 | O2: =L2+M2+N2 | P2: =G2+I2+J2+O2 | Q2: 2023-06-15 | R2: Semi-Monthly | S2: Exempt | T2: Austin, TX
A3: HR002 | B3: Priya Nair | C3: Talent Acquisition | D3: Talent Acquisition Coordinator | E3: L2 | F3: Full-Time | G3: 58000 | H3: 0.05 | I3: =G3*H3 | J3: 0 | K3: =G3+I3+J3 | L3: 9600 | M3: 2900 | N3: 1200 | O3: =L3+M3+N3 | P3: =G3+I3+J3+O3 | Q3: 2024-01-08 | R3: Semi-Monthly | S3: Non-Exempt | T3: Austin, TX
A4: HR003 | B4: Marcus Webb | C4: HR Business Partner | D4: Sr. HR Business Partner | E4: L4 | F4: Full-Time | G4: 105000 | H4: 0.15 | I4: =G4*H4 | J4: 5000 | K4: =G4+I4+J4 | L4: 9600 | M4: 5250 | N4: 1500 | O4: =L4+M4+N4 | P4: =G4+I4+J4+O4 | Q4: 2021-03-22 | R4: Semi-Monthly | S4: Exempt | T4: Austin, TX
A5: HR004 | B5: Aisha Okafor | C5: HR Business Partner | D5: HR Business Partner | E5: L3 | F5: Full-Time | G5: 88000 | H5: 0.1 | I5: =G5*H5 | J5: 0 | K5: =G5+I5+J5 | L5: 9600 | M5: 4400 | N5: 1200 | O5: =L5+M5+N5 | P5: =G5+I5+J5+O5 | Q5: 2022-09-12 | R5: Semi-Monthly | S5: Exempt | T5: Austin, TX
A6: HR005 | B6: Diana Chen | C6: Compensation & Benefits | D6: Compensation Analyst | E6: L3 | F6: Full-Time | G6: 92000 | H6: 0.1 | I6: =G6*H6 | J6: 0 | K6: =G6+I6+J6 | L6: 9600 | M6: 4600 | N6: 1200 | O6: =L6+M6+N6 | P6: =G6+I6+J6+O6 | Q6: 2022-05-01 | R6: Semi-Monthly | S6: Exempt | T6: Austin, TX
A7: HR006 | B7: Tomás Rivera | C7: Compensation & Benefits | D7: Benefits Specialist | E7: L2 | F7: Full-Time | G7: 62000 | H7: 0.05 | I7: =G7*H7 | J7: 0 | K7: =G7+I7+J7 | L7: 9600 | M7: 3100 | N7: 1200 | O7: =L7+M7+N7 | P7: =G7+I7+J7+O7 | Q7: 2023-11-20 | R7: Semi-Monthly | S7: Non-Exempt | T7: Austin, TX
A8: HR007 | B8: Keisha Daniels | C8: Payroll | D8: Payroll Manager | E8: L4 | F8: Full-Time | G8: 98000 | H8: 0.12 | I8: =G8*H8 | J8: 0 | K8: =G8+I8+J8 | L8: 9600 | M8: 4900 | N8: 1500 | O8: =L8+M8+N8 | P8: =G8+I8+J8+O8 | Q8: 2020-07-06 | R8: Semi-Monthly | S8: Exempt | T8: Austin, TX
A9: HR008 | B9: Samira Patel | C9: Learning & Development | D9: L&D Specialist | E9: L3 | F9: Full-Time | G9: 78000 | H9: 0.08 | I9: =G9*H9 | J9: 0 | K9: =G9+I9+J9 | L9: 9600 | M9: 3900 | N9: 1200 | O9: =L9+M9+N9 | P9: =G9+I9+J9+O9 | Q9: 2023-02-14 | R9: Semi-Monthly | S9: Exempt | T9: Austin, TX
A10: HR009 | B10: Ben Carter | C10: HR Operations | D10: HR Operations Manager | E10: L4 | F10: Full-Time | G10: 102000 | H10: 0.12 | I10: =G10*H10 | J10: 5000 | K10: =G10+I10+J10 | L10: 9600 | M10: 5100 | N10: 1500 | O10: =L10+M10+N10 | P10: =G10+I10+J10+O10 | Q10: 2019-10-01 | R10: Semi-Monthly | S10: Exempt | T10: Austin, TX
A11: HR010 | B11: Fatima Hassan | C11: HR Operations | D11: HR Compliance Specialist | E11: L3 | F11: Full-Time | G11: 82000 | H11: 0.08 | I11: =G11*H11 | J11: 0 | K11: =G11+I11+J11 | L11: 9600 | M11: 4100 | N11: 1200 | O11: =L11+M11+N11 | P11: =G11+I11+J11+O11 | Q11: 2022-04-18 | R11: Semi-Monthly | S11: Exempt | T11: Austin, TX
A12: HR011 | B12: Nina Torres | C12: Employee Engagement | D12: Employee Experience Manager | E12: L4 | F12: Full-Time | G12: 95000 | H12: 0.12 | I12: =G12*H12 | J12: 0 | K12: =G12+I12+J12 | L12: 9600 | M12: 4750 | N12: 1500 | O12: =L12+M12+N12 | P12: =G12+I12+J12+O12 | Q12: 2021-08-30 | R12: Semi-Monthly | S12: Exempt | T12: Austin, TX
A13: TOTAL | G13: =SUM(G2:G12) | I13: =SUM(I2:I12) | J13: =SUM(J2:J12) | K13: =SUM(K2:K12) | L13: =SUM(L2:L12) | M13: =SUM(M2:M12) | N13: =SUM(N2:N12) | O13: =SUM(O2:O12) | P13: =SUM(P2:P12)

Sheet Summary Dashboard
A1: ImpactIQ — HR Activity & Compensation Summary
A2: Sample Data | March 2026 | 11 HR Employees
A4: Department | B4: Headcount | C4: Total Base Payroll | D4: Avg Base Salary | E4: Total Activities | F4: Total Hours | G4: Employees Impacted
A5: Talent Acquisition | B5: 2 | C5: =SUMIF('Employee Compensation'!C:C,A6,'Employee Compensation'!G:G) | D5: =C6/B6 | E5: 10 | F5: 17 | G5: 15
A6: HR Business Partner | B6: 2 | C6: =SUMIF('Employee Compensation'!C:C,A7,'Employee Compensation'!G:G) | D6: =C7/B7 | E6: 10 | F6: 29 | G6: 374
A7: Compensation & Benefits | B7: 2 | C7: =SUMIF('Employee Compensation'!C:C,A8,'Employee Compensation'!G:G) | D7: =C8/B8 | E7: 10 | F7: 28 | G7: 985
A8: Payroll | B8: 1 | C8: =SUMIF('Employee Compensation'!C:C,A9,'Employee Compensation'!G:G) | D8: =C9/B9 | E8: 5 | F8: 16 | G8: 647
A9: Learning & Development | B9: 1 | C9: =SUMIF('Employee Compensation'!C:C,A10,'Employee Compensation'!G:G) | D9: =C10/B10 | E9: 5 | F9: 19 | G9: 379
A10: HR Operations | B10: 2 | C10: =SUMIF('Employee Compensation'!C:C,A11,'Employee Compensation'!G:G) | D10: =C11/B11 | E10: 10 | F10: 36 | G10: 1501
A11: Employee Engagement | B11: 1 | C11: =SUMIF('Employee Compensation'!C:C,A12,'Employee Compensation'!G:G) | D11: =C12/B12 | E11: 5 | F11: 15 | G11: 461
A14: KEY METRICS
A15: Total HR Headcount | B15: =COUNTA('Employee Compensation'!A2:A12)
A16: Total Annual HR Payroll | B16: =SUM('Employee Compensation'!G2:G12)
A17: Avg HR Base Salary | B17: =AVERAGE('Employee Compensation'!G2:G12)
A18: Total Target Comp (all in) | B18: =SUM('Employee Compensation'!P2:P12)
A19: Total Activities Logged | B19: 55
A20: Total Hours Logged | B20: =SUMIF('HR Activity Log'!K:K,"Completed",'HR Activity Log'!H:H)
A21: Distinct Activity Types | B21: 11
A22: Activities Completed | B22: =COUNTIF('HR Activity Log'!L:L,"Completed")
A23: Activities In Progress | B23: =COUNTIF('HR Activity Log'!L:L,"In Progress")
A24: Total Employees Impacted | B24: =SUM('HR Activity Log'!I:I)
